Workbook

Sheet Capacity_8_hrs
A1: Sprint #1: 02/14 to 02/25
A2: Name | B2: Daily capacity (hrs) | C2: Sprint 1 capacity (hrs) | D2: total sprint # of days | E2: sprint planning (days) | F2: sprint review/retro (days) | G2: QA+Defects fixing+defects retesting (hrs) | H2: Holidays/PTO (days) | I2: Active dev days
A3: Kumar Anagandula, Harish | B3: 6 | C3: =B3*I3 -> 48 | D3: 10 | E3: 1 | F3: 0 | G3: 0 | H3: 1 | I3: =D3-E3-F3-G3-H3 -> 8
A4: Geever, Vineeth Paul | B4: 0 | C4: =B4*I4 -> 0 | D4: 10 | E4: 1 | F4: 0 | G4: 0 | H4: 0 | I4: =D4-E4-F4-G4-H4 -> 9
A5: Surve, Diptesh Dattaram | B5: 8 | C5: =B5*I5 -> 72 | D5: 10 | E5: 1 | F5: 0 | G5: 0 | H5: 0 | I5: =D5-E5-F5-G5-H5 -> 9
A6: Kumari, Dolly | B6: 0 | C6: =B6*I6 -> 0 | D6: 10 | E6: 1 | F6: 0 | G6: 0 | H6: 0 | I6: =D6-E6-F6-G6-H6 -> 9
A7: Naresh, Parnapalli | B7: 8 | C7: =B7*I7 -> 72 | D7: 10 | E7: 1 | F7: 0 | G7: 0 | H7: 0 | I7: =D7-E7-F7-G7-H7 -> 9
A8: Begum, Tadimarri Akhila | B8: 8 | C8: =B8*I8 -> 72 | D8: 10 | E8: 1 | F8: 0 | G8: 0 | H8: 0 | I8: =D8-E8-F8-G8-H8 -> 9
A9: Para, Mohsin Hussain | B9: 8 | C9: =B9*I9 -> 72 | D9: 10 | E9: 1 | F9: 0 | G9: 0 | H9: 0 | I9: =D9-E9-F9-G9-H9 -> 9
A13: Total capacity | C13: =SUM(C3:C9) -> 336 | F13: Prod Support | G13: hrs
A14: Actual Dev + UT | C14: ='PBIs Sprint 1'!J5 -> 126.5 | F14: Antra | G14: 40
A15: Actual Dev + QA | C15: ='PBIs Sprint 1'!M5 -> 176.5 | F15: Durga | G15: 40
A16: Daily scrum | C16: =1*10*5 -> 50 | D16: 0.5 hrs each day for each member | F16: Geever, Vineeth Paul | G16: 80 | H16: 1863854 | I16: [Prod] EMA Mailbox sync issues
A17: Bug fixes + DevOps (code review/review comments incorporation/build activities/BSA clarification) | C17: =C14*B84/100 -> 44.275 | D17: ~ 35% of Actual Dev + UT | F17: Kumari, Dolly | G17: 80
A18: standard buffer | C18: =C13*B83/100 -> 67.2 | D18: ~ buffer is 20% of total capacity | F18: Preeti | G18: 40 | H18: QA activities
A19: Actual buffer | C19: =C13-C15-C16-C17 -> 65.225
A22: Sprint# 2: 02/28/2022 to 03/11/2022
A23: Name | B23: Daily capacity | C23: Sprint 2 capacity (hrs) | D23: total sprint# of days | E23: sprint planning (days) | F23: sprint review/retro | G23: QA+Defects fixing+defects retesting (hrs) | H23: Holidays/PTO (days) | I23: Active dev days
A24: Kumar Anagandula, Harish | B24: 6 | C24: =B24*I24 -> 54 | D24: 10 | E24: 1 | F24: 0 | G24: 0 | H24: 0 | I24: =D24-E24-F24-G24-H24 -> 9
A25: Geever, Vineeth Paul | B25: 0 | C25: =B25*I25 -> 0 | D25: 10 | E25: 1 | F25: 0 | G25: 0 | H25: 0 | I25: =D25-E25-F25-G25-H25 -> 9
A26: Surve, Diptesh Dattaram | B26: 8 | C26: =B26*I26 -> 72 | D26: 10 | E26: 1 | F26: 0 | G26: 0 | H26: 0 | I26: =D26-E26-F26-G26-H26 -> 9
A27: Kumari, Dolly | B27: 8 | C27: =B27*I27 -> 72 | D27: 10 | E27: 1 | F27: 0 | G27: 0 | H27: 0 | I27: =D27-E27-F27-G27-H27 -> 9
A28: Naresh, Parnapalli | B28: 0 | C28: =B28*I28 -> 0 | D28: 10 | E28: 1 | F28: 0 | G28: 0 | H28: 0 | I28: =D28-E28-F28-G28-H28 -> 9
A29: Begum, Tadimarri Akhila | B29: 8 | C29: =B29*I29 -> 72 | D29: 10 | E29: 1 | F29: 0 | G29: 0 | H29: 0 | I29: =D29-E29-F29-G29-H29 -> 9
A30: Para, Mohsin Hussain | B30: 8 | C30: =B30*I30 -> 72 | D30: 10 | E30: 1 | F30: 0 | G30: 0 | H30: 0 | I30: =D30-E30-F30-G30-H30 -> 9
A32: Total capacity | C32: =SUM(C24:C30) -> 342
A33: Actual Dev + UT | C33: ='PBIs Sprint 2'!J5 -> 136.85 | F33: Prod Support | G33: hrs
A34: Actual Dev + QA | C34: ='PBIs Sprint 2'!M5 -> 202.85 | F34: Antra | G34: 40
A35: Daily scrum | C35: =1*10*5 -> 50 | D35: 0.5 hrs each day for each member | F35: Durga | G35: 40
A36: Bug fixes + DevOps (code review/review comments incorporation/build activties/BSA clarification) | C36: =C33*B84/100 -> 47.8975 | D36: ~ 35% of Actual Dev + UT | F36: Geever, Vineeth Paul | G36: 80
A37: Standard buffer | C37: =C32*B83/100 -> 68.4 | D37: ~ buffer is 20% of total capacity | F37: Naresh, Parnapalli | G37: 80
A38: Actual buffer | C38: =C32-SUM(C34:C36) -> 41.2525
A40: Sprint# 3 - 03/14/2022 to 03/25/2022
A41: Name | B41: Daily capacity | C41: Sprint 1 capacity (hrs) | D41: total sprint# of days | E41: sprint planning (days) | F41: sprint review/retro | G41: QA+Defects fixing+defects retesting (hrs) | H41: Holidays/PTO (days) | I41: Active dev days
A42: Kumar Anagandula, Harish | B42: 6 | C42: =B42*I42 -> 48 | D42: 10 | E42: 1 | F42: 0 | G42: 0 | H42: 1 | I42: =D42-E42-F42-G42-H42 -> 8
A43: Geever, Vineeth Paul | B43: 0 | C43: =B43*I43 -> 0 | D43: 10 | E43: 1 | F43: 0 | G43: 0 | H43: 1 | I43: =D43-E43-F43-G43-H43 -> 8
A44: Surve, Diptesh Dattaram | B44: 0 | C44: =B44*I44 -> 0 | D44: 10 | E44: 1 | F44: 0 | G44: 0 | H44: 1 | I44: =D44-E44-F44-G44-H44 -> 8
A45: Kumari, Dolly | B45: 8 | C45: =B45*I45 -> 48 | D45: 10 | E45: 1 | F45: 0 | G45: 0 | H45: =1+1+1 -> 3 | I45: =D45-E45-F45-G45-H45 -> 6
A46: Naresh, Parnapalli | B46: 8 | C46: =B46*I46 -> 64 | D46: 10 | E46: 1 | F46: 0 | G46: 0 | H46: 1 | I46: =D46-E46-F46-G46-H46 -> 8
A47: Begum, Tadimarri Akhila | B47: 8 | C47: =B47*I47 -> 64 | D47: 10 | E47: 1 | F47: 0 | G47: 0 | H47: 1 | I47: =D47-E47-F47-G47-H47 -> 8
...

Sheet BAU
A1: ID | B1: Title | C1: State | D1: Assigned To | E1: Remaining Work | F1: Iteration Path | G1: Effort
A2: 1863854 | B2: [Prod] EMA Mailbox sync issues | C2: Committed | D2: Vineeth Paul Geever | F2: iConfirm\iConfirm 9.1.2 Release\iConfirm 9.1.2 Release - Sprint 3 | G2: 60 | K2: 1. mailboxes are not syncing: there is a job that runs every 10 mins to check if there is new email to sync in DB so that it is visible in iConfirm. If each GEO has 100+projects, EMA has issue, every few hrs we get email that mailbox is syncing 2. emails are missing from Inbox: mailbox has an attachment, we fetch data from outlook, download encrypted attachment, and save in DB, not getting saved in DB, emails not seen in iConfirm, not related to size, DB load | L2: Console App: query emailbox, fetch attachment, try to encrpt and save to DB | M2: partial solution in Feb release. End point URL. EWS team has given end points, end points are old and they missed to inform about new URLs. In stage its implemented. Only regression is done. Specific to EMA Pending stuff: Rishi grouped frequently occuring issues, EWS service is throwing errors, need to analyze
A3: 1876925 | B3: [Prod] PDF attachments in emails synced in Iconfirm are not visible | C3: Committed | D3: Parnapalli Naresh | F3: iConfirm\iConfirm 9.1.2 Release\iConfirm 9.1.2 Release - Sprint 3 | G3: 18 | K3: may be failing because of attachment | L3: addressed by Consle app
A4: 1892914 | B4: [Prod] Email not syncing to Project Inbox | C4: Committed | D4: Parnapalli Naresh | E4: 33 | F4: iConfirm\iConfirm 9.1.2 Release\iConfirm 9.1.2 Release - Sprint 3 | G4: 45 | K4: may be failing because of attachment | L4: addressed by Consle app
A5: 1898950 | B5: [Prod] Console App Utility | C5: Committed | D5: Parnapalli Naresh | E5: 8 | F5: iConfirm\iConfirm 9.1.2 Release\iConfirm 9.1.2 Release - Sprint 3 | G5: 40
A6: 1899374 | B6: [Prod] Iconfirm INC4574249 : Maintenance page | C6: Done | D6: Harish Kumar Anagandula | F6: iConfirm\iConfirm 9.1.2 Release\iConfirm 9.1.2 Release - Sprint 3
A7: 1896188 | B7: Iconfirm - remove a domain from restricted list | C7: Committed | D7: Antra Lnu | E7: 8 | F7: iConfirm\iConfirm 9.1.2 Release\iConfirm 9.1.2 Release - Sprint 3
A8: 1901285 | B8: Iconfirm - Mailbox requires rename -9th Feb | C8: Done | D8: Antra Lnu | F8: iConfirm\iConfirm 9.1.2 Release\iConfirm 9.1.2 Release - Sprint 3
A9: 1882710 | B9: [Prod] Iconfirm - Automated set reminders not sending | C9: Committed | D9: Dolly Kumari | F9: iConfirm\iConfirm 9.1.2 Release\iConfirm 9.1.2 Release - Sprint 3 | G9: 30 | H9: new PBI to track | I9: awaiting pripiritization | J9: Preeti should create PBI
A10: 1854596 | B10: [Tech] Investigate the reason for locking during bulk inserts | C10: Committed | D10: Parnapalli Naresh | E10: 5 | F10: iConfirm\iConfirm 9.1.2 Release\iConfirm 9.1.2 Release - Sprint 3 | G10: 50 | J10: screen getting stuck when confirmation is sent. Deadlock issue, team found indexes missing, blocker is gone, indexes are in prod, from Jan start issue not reproducible, too many open connections though, based on bandwidth team can analyze | K10: ON HOLD
A12: Open as query

Sheet POD Structure
A1: Enhancement POD | B1: Role | D1: Prod Support | E1: Role
A2: Kumar Anagandula, Harish | B2: Dev | D2: Geever, Vineeth Paul | E2: Dev
A3: Surve, Diptesh Dattaram | B3: Dev | D3: Naresh, Parnapalli | E3: Dev
A4: Kumari, Dolly | B4: Dev
A5: Begum, Tadimarri Akhila | B5: QA
A6: Para, Mohsin Hussain | B6: QA

Sheet Timeline
B1: dev start | C1: dev completion | D1: QA sign off UAT deployment | F1: UAT sign off
A2: Sprint 1
A3: Sprint 2
A4: Release QA Regression
A5: UAT Regression

Sheet PBIs Sprint 1
A1: ID | B1: Work Item Type | C1: Title 2 | D1: Iteration Path | E1: Story Points | F1: BE(Hr) | G1: FE(Hr) | H1: SQL(Hr) | I1: UT | J1: Dev + UT | K1: Test Design | L1: Test Execution | M1: Dev + QA Estimate | N1: Comments | O1: Sprint | P1: QA Deployment | Q1: Team assignment | R1: Dev Start Date | S1: Dev/UT Completion | T1: Test cases start | U1: Test cases completion | V1: QA start | W1: QA completion | X1: QA Owner
A2: 1872472 | B2: PBI | C2: CCI - API changes to sync the CCI confirmations existing in Iconfirm | F2: 45 | G2: 0 | H2: 0 | I2: =SUM(F2:H2)*Capacity_8_hrs!$B$85 -> 6.75 | J2: =SUM(F2:I2) -> 51.75 | K2: 4 | L2: 6 | M2: =SUM(J2:L2) -> 61.75 | Q2: Diptesh
A3: 1846206 | B3: PBI | C3: CCI - API changes | F3: 30 | G3: 0 | H3: 0 | I3: =SUM(F3:H3)*Capacity_8_hrs!$B$85 -> 4.5 | J3: =SUM(F3:I3) -> 34.5 | K3: 8 | L3: 16 | M3: =SUM(J3:L3) -> 58.5 | N3: sync confirmations.com, after a while, they disappear from iConfirm, don’t know the frequency | Q3: Harish
A4: 1898950 | B4: PBI | C4: Console App | F4: 35 | G4: 0 | H4: 0 | I4: =SUM(F4:H4)*Capacity_8_hrs!$B$85 -> 5.25 | J4: =SUM(F4:I4) -> 40.25 | K4: 8 | L4: 8 | M4: =SUM(J4:L4) -> 56.25 | N4: dev in progress, app team | Q4: Naresh
A5: Total | I5: =SUM(I2:I4) -> 16.5 | J5: =SUM(J2:J4) -> 126.5 | K5: =SUM(K2:K4) -> 20 | L5: =SUM(L2:L4) -> 30 | M5: =SUM(M2:M4) -> 176.5

Sheet PBIs Sprint 2
A1: ID | B1: Work Item Type | C1: Title 2 | D1: Iteration Path | E1: Story Points | F1: BE(Hr) | G1: FE(Hr) | H1: SQL(Hr) | I1: UT | J1: Dev + UT | K1: Test Design | L1: Test Execution | M1: Dev + QA Estimate | N1: Comments | O1: Sprint | P1: QA Deployment | Q1: Team assignment | R1: Dev Start Date | S1: Dev/UT Completion | T1: Test cases start | U1: Test cases completion | V1: QA start | W1: QA completion | X1: QA Owner
A2: 1851132 | B2: PBI | C2: OPM Container Mapping Updates | F2: 54 | G2: 0 | H2: 0 | I2: =SUM(F2:H2)*Capacity_8_hrs!$B$85 -> 8.1 | J2: =SUM(F2:I2) -> 62.1 | K2: 14 | L2: 30 | M2: =SUM(J2:L2) -> 106.1 | N2: Bolivia, Hungary, Gibraltar | Q2: Harish
A3: 1854595 | B3: PBI | C3: [Tech] Update Omnia links | H3: 20 | I3: =SUM(F3:H3)*Capacity_8_hrs!$B$85 -> 3 | J3: =SUM(F3:I3) -> 23 | K3: 4 | L3: 8 | M3: =SUM(J3:L3) -> 35 | N3: no description and no AC, App team to update description, dacpac change | Q3: Dolly | X3: Akhila
A4: 1888098 | B4: PBI | C4: CCI - Change the ADFS authentication to AD authentication | F4: 45 | G4: 0 | H4: 0 | I4: =SUM(F4:H4)*Capacity_8_hrs!$B$85 -> 6.75 | J4: =SUM(F4:I4) -> 51.75 | K4: 4 | L4: 6 | M4: =SUM(J4:L4) -> 61.75 | N4: no description, AC is present, Preeti to work with Harish to get description. Leverage technical discussion email with ADFS. Need to setup call with ADFS | Q4: Diptesh
A5: Total | I5: =SUM(I2:I4) -> 17.85 | J5: =SUM(J2:J4) -> 136.85 | K5: =SUM(K2:K4) -> 22 | L5: =SUM(L2:L4) -> 44 | M5: =SUM(M2:M4) -> 202.85

Sheet PBIs Sprint 3
A1: ID | B1: Work Item Type | C1: Title 2 | D1: Iteration Path | E1: Story Points | F1: BE(Hr) | G1: FE(Hr) | H1: SQL(Hr) | I1: UT | J1: Dev + UT | K1: Test Design | L1: Test Execution | M1: Dev + QA Estimate | N1: Comments | O1: Sprint | P1: QA Deployment | Q1: Team assignment | R1: Dev Start Date | S1: Dev/UT Completion | T1: Test cases start | U1: Test cases completion | V1: QA start | W1: QA completion | X1: QA Owner
A2: 1828981 | B2: PBI | C2: [Cookie management] [Tech] - Implement cookie banner | F2: 37 | G2: 0 | H2: 0 | I2: =SUM(F2:H2)*Capacity_8_hrs!$B$85 -> 5.55 | J2: =SUM(F2:I2) -> 42.55 | K2: 16 | L2: 16 | M2: =SUM(J2:L2) -> 74.55 | Q2: Naresh
A3: 1866451 | B3: PBI | C3: [Cookie management] - Provide Cookie Notice page | F3: 16 | G3: 0 | H3: 0 | I3: =SUM(F3:H3)*Capacity_8_hrs!$B$85 -> 2.4 | J3: =SUM(F3:I3) -> 18.4 | K3: 8 | L3: 8 | M3: =SUM(J3:L3) -> 34.4 | Q3: Dolly
A4: 1866461 | B4: PBI | C4: [Cookie management] - Add 'Manage Cookie Preferences' To User Settings | F4: 8 | G4: 0 | H4: 0 | I4: =SUM(F4:H4)*Capacity_8_hrs!$B$85 -> 1.2 | J4: =SUM(F4:I4) -> 9.2 | K4: 8 | L4: 8 | M4: =SUM(J4:L4) -> 25.2 | Q4: Harish
A5: Total | I5: =SUM(I2:I4) -> 9.15 | J5: =SUM(J2:J4) -> 70.15 | K5: =SUM(K2:K4) -> 32 | L5: =SUM(L2:L4) -> 32 | M5: =SUM(M2:M4) -> 134.15

Sheet PBIs Sprint 4
A1: ID | B1: Work Item Type | C1: Title 2 | D1: Iteration Path | E1: Story Points | F1: BE(Hr) | G1: FE(Hr) | H1: SQL(Hr) | I1: UT | J1: Dev + UT | K1: Test Design | L1: Test Execution | M1: Dev + QA Estimate | N1: Comments | O1: Sprint | P1: QA Deployment | Q1: Team assignment | R1: Dev Start Date | S1: Dev/UT Completion | T1: Test cases start | U1: Test cases completion | V1: QA start | W1: QA completion | X1: QA Owner
A2: 1885071 | B2: PBI | C2: [Prod] AME users getting directed to maintenance page | F2: 0 | G2: 0 | H2: 40 | I2: =SUM(F2:H2)*Capacity_8_hrs!$B$85 -> 6 | J2: =SUM(F2:I2) -> 46 | K2: 6 | L2: 16 | M2: =SUM(J2:L2) -> 68 | N2: across GEOs. Update script. 70 container DBs | Q2: Dolly
A3: 1885803 | B3: PBI | C3: [Prod] PDF Generation Error | F3: 30 | G3: 0 | H3: 0 | I3: =SUM(F3:H3)*Capacity_8_hrs!$B$85 -> 4.5 | J3: =SUM(F3:I3) -> 34.5 | K3: 0 | L3: 0 | M3: =SUM(J3:L3) -> 34.5 | N3: dev team to estimate, only AC is present | Q3: Diptesh
A4: Total | I4: =SUM(I2:I3) -> 10.5 | J4: =SUM(J2:J3) -> 80.5 | K4: =SUM(K2:K3) -> 6 | L4: =SUM(L2:L3) -> 16 | M4: =SUM(M2:M3) -> 102.5

Sheet todo
A1: ID | B1: Type | C1: Title | D1: Action Item | E1: Owner
A2: 1888098 | B2: PBI | C2: CCI - Change the ADFS authentication to AD authentication | D2: Kunal to setup call with ADFS team to get details | E2: Kunal
A3: 1854595 | B3: PBI | C3: [Tech] Update Omnia links | D3: no description and no AC, App team to update description, dacpac change | E3: Kunal
A4: 1885803 | B4: PBI | C4: [Prod] PDF Generation Error | D4: estimates to be revised, description is missing | E4: Marrisa
B5: PBI | C5: Console App
A8: issues
A9: tasks not updated

Sheet PBIs Sprint 3 old
A1: ID | B1: Work Item Type | C1: Title 2 | D1: Iteration Path | E1: Story Points | F1: BE(Hr) | G1: FE(Hr) | H1: SQL(Hr) | I1: UT | J1: Dev + UT | K1: Test Design | L1: Test Execution | M1: Dev + QA Estimate | N1: Comments | O1: Sprint | P1: QA Deployment | Q1: Team assignment | R1: Dev Start Date | S1: Dev/UT Completion | T1: QA Start | U1: QA completion | V1: QA Owner
C2: Hungary container rename | F2: 2 | J2: =SUM(F2:I2) -> 2 | K2: 4 | L2: 4 | M2: =SUM(J2:L2) -> 10 | O2: Sprint 3
C3: Cookie project | J3: =SUM(F3:I3) -> 0 | M3: =SUM(J3:L3) -> 0 | O3: Sprint 3
C4: Approved approach for Gibraltar removal | F4: 2 | J4: =SUM(F4:I4) -> 2 | K4: 4 | L4: 4 | M4: =SUM(J4:L4) -> 10 | O4: Sprint 3
C5: bug…830 | J5: =SUM(F5:I5) -> 0 | M5: =SUM(J5:L5) -> 0 | O5: Sprint 3
C6: perm fix | J6: =SUM(F6:I6) -> 0 | M6: =SUM(J6:L6) -> 0 | O6: Sprint 3
E9: =SUM(E2:E6) -> 0 | F9: =SUM(F2:F6) -> 4 | G9: =SUM(G2:G6) -> 0 | H9: =SUM(H2:H6) -> 0 | I9: =SUM(I2:I6) -> 0 | J9: =SUM(J2:J6) -> 4 | K9: =SUM(K2:K6) -> 8 | L9: =SUM(L2:L6) -> 8 | M9: =SUM(M2:M6) -> 20
A11: UT % | C11: 0.15

Sheet PBIs Sprint 2 old
A1: ID | B1: Work Item Type | C1: Title 2 | D1: Iteration Path | E1: Story Points | F1: BE(Hr) | G1: FE(Hr) | H1: SQL(Hr) | I1: UT | J1: Dev + UT | K1: Test Design | L1: Test Execution | M1: Dev + QA Estimate | N1: Comments | O1: Sprint | P1: QA Deployment | Q1: Team assignment | R1: Dev Start Date | S1: Dev/UT Completion | T1: QA Start | U1: QA completion | V1: QA Owner
C2: Enable browser caching of static files to increase performance | F2: 24 | G2: 0 | H2: 0 | I2: =SUM(F2:H2)*$C$12 -> 3.6 | J2: =SUM(F2:I2) -> 27.6 | K2: 0 | L2: 36 | M2: =SUM(J2:L2) -> 63.6 | O2: Sprint 2 | P2: 44594 | Q2: Vaibhav | R2: 44592 | S2: 44594 | T2: 44595 | U2: 44600 | V2: Ranjit/Anupam
B3: UST | C3: Remove unused code | F3: 18 | G3: 9 | H3: 9 | I3: =SUM(F3:H3)*$C$12 -> 5.4 | J3: =SUM(F3:I3) -> 41.4 | K3: 0 | L3: 0 | M3: =SUM(J3:L3) -> 41.4 | O3: Sprint 2 | P3: 44596 | Q3: Prathamesh | R3: 44592 | S3: 44596 | T3: 44595 | U3: 44600 | V3: Ranjit/Anupam
C4: Enable appinsights for cron jobs | M4: =SUM(J4:L4) -> 0 | N4: may not have to implement. | O4: Sprint 2
B5: UST | C5: Upgrade Racer model to latest version (this library is used for real-time data synchronization) | F5: 24 | I5: =SUM(F5:H5)*$C$12 -> 3.6 | J5: =SUM(F5:I5) -> 27.6 | K5: 0 | L5: 0 | M5: =SUM(J5:L5) -> 27.6 | O5: Sprint 2 | P5: 44595 | Q5: Prasad | R5: 44592 | S5: 44595 | T5: 44595 | U5: 44600 | V5: Ranjit/Anupam
B6: UST | C6: Implement localization for Template & Country manager screen | I6: =SUM(F6:H6)*$C$12 -> 0 | J6: =SUM(F6:I6) -> 0 | M6: =SUM(J6:L6) -> 0 | N6: Functional | O6: Sprint 2
A7: 1857138 | B7: Bug | C7: Project count not updated | D7: Scribe\Scribe 5.3.1 Release - Sprint 2 | F7: 8 | G7: 0 | H7: 0 | I7: =SUM(F7:H7)*$C$18 -> 0 | J7: =SUM(F7:I7) -> 8 | K7: 4 | L7: 16 | M7: =SUM(J7:L7) -> 28 | N7: dev testing | O7: Sprint 2 | P7: 44592 | Q7: Prasad | R7: 44580 | S7: 44580 | T7: 44592 | U7: 44594 | V7: Anupam
A8: 1854752 | B8: Bug | C8: Ctrl Y and Ctrl Z do not work while editing deliverables | D8: Scribe\Scribe 5.3.1 Release - Sprint 1 | N8: so far not reproducible - as of 01/17 | O8: Sprint 2 | Q8: Raghu | V8: Anupam
E10: =SUM(E2:E8) -> 0 | F10: =SUM(F2:F8) -> 74 | G10: =SUM(G2:G8) -> 9 | H10: =SUM(H2:H8) -> 9 | I10: =SUM(I2:I8) -> 12.6 | J10: =SUM(J2:J8) -> 104.6 | K10: =SUM(K2:K8) -> 4 | L10: =SUM(L2:L8) -> 52 | M10: =SUM(M2:M8) -> 160.6
A12: UT % | C12: 0.15

Sheet Sheet1
A1: OPM access
A2: ADO access
A3: https://qscribe.deloitte.com/

Sheet SP Estimation guidelines
A1: As the story points represent the overall effort taken by the developers to create a story, the team should estimate the story point concerning all the factors that affect the effort of the developer. These include:
A3: The amount of work that has to be done
A4: The complexity of the task or work
A5: Any uncertainty or risk while doing the work
A6: These three factors have major impacts while estimating a story point.
A8: Whats followed: Estimation Process of Planning Poker
A10: T-shirt sizing method | B10: SP | D10: Complexity | E10: SP | F10: Tentative | H10: ​Story Points | I10: ​Time Frame | J10: ​Example | K10: hr | L10: assumption | M10: hr | N10: assumption
A11: X-Small | B11: 1 | D11: very simple | E11: 1 | F11: 4–12 hours | H11: 1 | I11: ​4 ideal hours | J11: Changing text on a label | K11: 4 | L11: 6 hrs/day | M11: 4 | N11: 7 hrs/day
A12: Small | B12: 2 | D12: simple | E12: 2 | F12: 10–20 hours | H12: ​2 | I12: 2-3 days, may require testing | J12: ​Adding a new field | K12: 12 to 18 | L12: 6 hrs/day | M12: 14 to 21 | N12: 7 hrs/day
A13: Medium | B13: 3 | D13: medium | E13: 3 | F13: 18-25 hours | H13: ​3 | I13: 4 days for 1 person | J13: ​Adding a new field that may appear in a few places within the application | K13: 24 | L13: 6 hrs/day | M13: 28 | N13: 7 hrs/day
A14: Large | B14: 5 | D14: complex | E14: 5 | F14: 25-40 hours | H14: ​5 | I14: 5 days for 1 person | J14: ​Design and adding a section to an existing page | K14: 30 to 40 | L14: 6 hrs/day | M14: 35 to 40 | N14: 7 hrs/day
A15: Extra-Large | B15: 8 | D15: Very Complex | E15: 8 | F15: 35-65 hours | H15: ​8 | I15: 10 days for 1 person | J15: Design and add a new basic page | K15: > 40 | L15: 6 hrs/day | M15: > 40 | N15: 7 hrs/day
A16: XXL | B16: 13 | D16: Very Very Complex | E16: 13 | F16: 60-90 hours | H16: ​13 | I16: ​15 days for 1 person | J16: Avoid this, try to break it down
H17: ​20 | I17: 1 month for 1 person | J17: ​Way too big to be included in a sprint, break it down
H18: ​40 | I18: 2 months for 1 person | J18: Way too big to be included in a sprint, break it down
